Workbook

Sheet ADDRESS
A1: Lease Abstract
A3: PROPERTY
A4: (INSERT CLIENT LOGO)
D5: Property Name: | G5: =_xlfn.XLOOKUP(D5, 'Reference Sheet'!A:A, 'Reference Sheet'!B:B, "Not Found") -> Not Found
D6: Property Address: | G6: =_xlfn.XLOOKUP(D6, 'Reference Sheet'!A:A, 'Reference Sheet'!B:B, "Not Found") -> Not Found
D7: Landlord: | G7: =_xlfn.XLOOKUP(D7, 'Reference Sheet'!A:A, 'Reference Sheet'!B:B, "Not Found") -> Not Found
D8: Landlord Entity: | G8: =_xlfn.XLOOKUP(D8, 'Reference Sheet'!A:A, 'Reference Sheet'!B:B, "Not Found") -> Not Found
D9: Building Square Footage: | G9: =_xlfn.XLOOKUP(D9, 'Reference Sheet'!A:A, 'Reference Sheet'!B:B, "Not Found") -> Not Found
D10: Place of Rent Payment: | G10: =_xlfn.XLOOKUP(D10, 'Reference Sheet'!A:A, 'Reference Sheet'!B:B, "Not Found") -> Not Found
A12: TENANT
A13: Tenant Name: | D13: =_xlfn.XLOOKUP(A13, 'Reference Sheet'!A:A, 'Reference Sheet'!B:B, "Not Found") -> Not Found | H13: Effective Date: | K13: =_xlfn.XLOOKUP(H13, 'Reference Sheet'!A:A, 'Reference Sheet'!B:B, "Not Found") -> Not Found
A14: Guarantor: | D14: =_xlfn.XLOOKUP(A14, 'Reference Sheet'!A:A, 'Reference Sheet'!B:B, "Not Found") -> Not Found | H14: Delivery Date: | K14: =_xlfn.XLOOKUP(H14, 'Reference Sheet'!A:A, 'Reference Sheet'!B:B, "Not Found") -> Not Found
A15: Suite Numbers: | D15: =_xlfn.XLOOKUP(A15, 'Reference Sheet'!A:A, 'Reference Sheet'!B:B, "Not Found") -> Not Found | H15: Commencement Date: | K15: =_xlfn.XLOOKUP(H15, 'Reference Sheet'!A:A, 'Reference Sheet'!B:B, "Not Found") -> Not Found
A16: Square Footage: | D16: =_xlfn.XLOOKUP(A16, 'Reference Sheet'!A:A, 'Reference Sheet'!B:B, "Not Found") -> Not Found | H16: Rent Commencement Date: | K16: =_xlfn.XLOOKUP(H16, 'Reference Sheet'!A:A, 'Reference Sheet'!B:B, "Not Found") -> Not Found
A17: Improvement Allowance: | D17: =_xlfn.XLOOKUP(A17, 'Reference Sheet'!A:A, 'Reference Sheet'!B:B, "Not Found") -> Not Found | H17: Expiration: | K17: =_xlfn.XLOOKUP(H17, 'Reference Sheet'!A:A, 'Reference Sheet'!B:B, "Not Found") -> Not Found
A18: Expiration of Allowance: | D18: =_xlfn.XLOOKUP(A18, 'Reference Sheet'!A:A, 'Reference Sheet'!B:B, "Not Found") -> Not Found | H18: Term: | K18: =_xlfn.XLOOKUP(H18, 'Reference Sheet'!A:A, 'Reference Sheet'!B:B, "Not Found") -> Not Found
A19: Extension Commencement Date: | D19: =_xlfn.XLOOKUP(A19, 'Reference Sheet'!A:A, 'Reference Sheet'!B:B, "Not Found") -> Not Found | H19: Extension Term Length: | K19: =_xlfn.XLOOKUP(H19, 'Reference Sheet'!A:A, 'Reference Sheet'!B:B, "Not Found") -> Not Found
A20: Security Deposit: | D20: =_xlfn.XLOOKUP(A20, 'Reference Sheet'!A:A, 'Reference Sheet'!B:B, "Not Found") -> Not Found
A21: First Month's Rent: | D21: =_xlfn.XLOOKUP(A21, 'Reference Sheet'!A:A, 'Reference Sheet'!B:B, "Not Found") -> Not Found
A22: Abated Rent (Gross or Net): | D22: =_xlfn.XLOOKUP(A22, 'Reference Sheet'!A:A, 'Reference Sheet'!B:B, "Not Found") -> Not Found
A23: Other Concessions: | H23: Moving Allowance:
A25: Amendments: | C25: None | E25: Date: | H25: Terms: | I25: =_xlfn.XLOOKUP(LEFT(H25,LEN(H25)-1), 'Reference Sheet'!A:A, 'Reference Sheet'!B:B, "N/A") -> N/A
C26: XXX Sixth | E26: Date: | F26: 42453 | H26: Terms: | I26: =_xlfn.XLOOKUP(LEFT(H26,LEN(H26)-1), 'Reference Sheet'!A:A, 'Reference Sheet'!B:B, "N/A") -> N/A
A28: MAXIMUM BASE RENT (Total Premises Square Footage)
A29: Period | G29: Annual Rate Per Square Foot | M29: Monthly Base Rent
A30: {=_xlfn.LET(_xlpm.startRow, MATCH("Period", 'Reference Sheet'!A:A, 0)+1, IF(ROW()-ROW($A$29)+1>9, "N/A", INDEX('Reference Sheet'!A:A, _xlpm.startRow+ROW()-ROW($A$29)-1)))} -> #N/A | G30: {=_xlfn.LET(_xlpm.headerRow, MATCH("Period", 'Reference Sheet'!A:A, 0), _xlpm.startRow, _xlpm.headerRow+1, IF(ROW()-ROW($A$29)+1>9, "N/A", IF(ISNUMBER(INDEX('Reference Sheet'!B:B, _xlpm.startRow+ROW()-ROW($A$29)-1)), INDEX('Reference Sheet'!B:B, _xlpm.startRow+ROW()-ROW($A$29)-1), "N/A")))} -> N/A | M30: {=_xlfn.LET(_xlpm.headerRow, MATCH("Period", 'Reference Sheet'!A:A, 0), _xlpm.startRow, _xlpm.headerRow+1, IF(ROW()-ROW($A$29)+1>9, "N/A", IF(ISNUMBER(INDEX('Reference Sheet'!C:C, _xlpm.startRow+ROW()-ROW($A$29)-1)), INDEX('Reference Sheet'!C:C, _xlpm.startRow+ROW()-ROW($A$29)-1), "N/A")))} -> N/A
A31: {=_xlfn.LET(_xlpm.startRow, MATCH("Period", 'Reference Sheet'!A:A, 0)+1, IF(ROW()-ROW($A$29)+1>9, "N/A", INDEX('Reference Sheet'!A:A, _xlpm.startRow+ROW()-ROW($A$29)-1)))} -> #N/A | G31: {=_xlfn.LET(_xlpm.headerRow, MATCH("Period", 'Reference Sheet'!A:A, 0), _xlpm.startRow, _xlpm.headerRow+1, IF(ROW()-ROW($A$29)+1>9, "N/A", IF(ISNUMBER(INDEX('Reference Sheet'!B:B, _xlpm.startRow+ROW()-ROW($A$29)-1)), INDEX('Reference Sheet'!B:B, _xlpm.startRow+ROW()-ROW($A$29)-1), "N/A")))} -> N/A | M31: {=_xlfn.LET(_xlpm.headerRow, MATCH("Period", 'Reference Sheet'!A:A, 0), _xlpm.startRow, _xlpm.headerRow+1, IF(ROW()-ROW($A$29)+1>9, "N/A", IF(ISNUMBER(INDEX('Reference Sheet'!C:C, _xlpm.startRow+ROW()-ROW($A$29)-1)), INDEX('Reference Sheet'!C:C, _xlpm.startRow+ROW()-ROW($A$29)-1), "N/A")))} -> N/A
A32: {=_xlfn.LET(_xlpm.startRow, MATCH("Period", 'Reference Sheet'!A:A, 0)+1, IF(ROW()-ROW($A$29)+1>9, "N/A", INDEX('Reference Sheet'!A:A, _xlpm.startRow+ROW()-ROW($A$29)-1)))} -> #N/A | G32: {=_xlfn.LET(_xlpm.headerRow, MATCH("Period", 'Reference Sheet'!A:A, 0), _xlpm.startRow, _xlpm.headerRow+1, IF(ROW()-ROW($A$29)+1>9, "N/A", IF(ISNUMBER(INDEX('Reference Sheet'!B:B, _xlpm.startRow+ROW()-ROW($A$29)-1)), INDEX('Reference Sheet'!B:B, _xlpm.startRow+ROW()-ROW($A$29)-1), "N/A")))} -> N/A | M32: {=_xlfn.LET(_xlpm.headerRow, MATCH("Period", 'Reference Sheet'!A:A, 0), _xlpm.startRow, _xlpm.headerRow+1, IF(ROW()-ROW($A$29)+1>9, "N/A", IF(ISNUMBER(INDEX('Reference Sheet'!C:C, _xlpm.startRow+ROW()-ROW($A$29)-1)), INDEX('Reference Sheet'!C:C, _xlpm.startRow+ROW()-ROW($A$29)-1), "N/A")))} -> N/A
A33: {=_xlfn.LET(_xlpm.startRow, MATCH("Period", 'Reference Sheet'!A:A, 0)+1, IF(ROW()-ROW($A$29)+1>9, "N/A", INDEX('Reference Sheet'!A:A, _xlpm.startRow+ROW()-ROW($A$29)-1)))} -> #N/A | G33: {=_xlfn.LET(_xlpm.headerRow, MATCH("Period", 'Reference Sheet'!A:A, 0), _xlpm.startRow, _xlpm.headerRow+1, IF(ROW()-ROW($A$29)+1>9, "N/A", IF(ISNUMBER(INDEX('Reference Sheet'!B:B, _xlpm.startRow+ROW()-ROW($A$29)-1)), INDEX('Reference Sheet'!B:B, _xlpm.startRow+ROW()-ROW($A$29)-1), "N/A")))} -> N/A | M33: {=_xlfn.LET(_xlpm.headerRow, MATCH("Period", 'Reference Sheet'!A:A, 0), _xlpm.startRow, _xlpm.headerRow+1, IF(ROW()-ROW($A$29)+1>9, "N/A", IF(ISNUMBER(INDEX('Reference Sheet'!C:C, _xlpm.startRow+ROW()-ROW($A$29)-1)), INDEX('Reference Sheet'!C:C, _xlpm.startRow+ROW()-ROW($A$29)-1), "N/A")))} -> N/A
A34: {=_xlfn.LET(_xlpm.startRow, MATCH("Period", 'Reference Sheet'!A:A, 0)+1, IF(ROW()-ROW($A$29)+1>9, "N/A", INDEX('Reference Sheet'!A:A, _xlpm.startRow+ROW()-ROW($A$29)-1)))} -> #N/A | G34: {=_xlfn.LET(_xlpm.headerRow, MATCH("Period", 'Reference Sheet'!A:A, 0), _xlpm.startRow, _xlpm.headerRow+1, IF(ROW()-ROW($A$29)+1>9, "N/A", IF(ISNUMBER(INDEX('Reference Sheet'!B:B, _xlpm.startRow+ROW()-ROW($A$29)-1)), INDEX('Reference Sheet'!B:B, _xlpm.startRow+ROW()-ROW($A$29)-1), "N/A")))} -> N/A | M34: {=_xlfn.LET(_xlpm.headerRow, MATCH("Period", 'Reference Sheet'!A:A, 0), _xlpm.startRow, _xlpm.headerRow+1, IF(ROW()-ROW($A$29)+1>9, "N/A", IF(ISNUMBER(INDEX('Reference Sheet'!C:C, _xlpm.startRow+ROW()-ROW($A$29)-1)), INDEX('Reference Sheet'!C:C, _xlpm.startRow+ROW()-ROW($A$29)-1), "N/A")))} -> N/A
A35: {=_xlfn.LET(_xlpm.startRow, MATCH("Period", 'Reference Sheet'!A:A, 0)+1, IF(ROW()-ROW($A$29)+1>9, "N/A", INDEX('Reference Sheet'!A:A, _xlpm.startRow+ROW()-ROW($A$29)-1)))} -> #N/A | G35: {=_xlfn.LET(_xlpm.headerRow, MATCH("Period", 'Reference Sheet'!A:A, 0), _xlpm.startRow, _xlpm.headerRow+1, IF(ROW()-ROW($A$29)+1>9, "N/A", IF(ISNUMBER(INDEX('Reference Sheet'!B:B, _xlpm.startRow+ROW()-ROW($A$29)-1)), INDEX('Reference Sheet'!B:B, _xlpm.startRow+ROW()-ROW($A$29)-1), "N/A")))} -> N/A | M35: {=_xlfn.LET(_xlpm.headerRow, MATCH("Period", 'Reference Sheet'!A:A, 0), _xlpm.startRow, _xlpm.headerRow+1, IF(ROW()-ROW($A$29)+1>9, "N/A", IF(ISNUMBER(INDEX('Reference Sheet'!C:C, _xlpm.startRow+ROW()-ROW($A$29)-1)), INDEX('Reference Sheet'!C:C, _xlpm.startRow+ROW()-ROW($A$29)-1), "N/A")))} -> N/A
A36: {=_xlfn.LET(_xlpm.startRow, MATCH("Period", 'Reference Sheet'!A:A, 0)+1, IF(ROW()-ROW($A$29)+1>9, "N/A", INDEX('Reference Sheet'!A:A, _xlpm.startRow+ROW()-ROW($A$29)-1)))} -> #N/A | G36: {=_xlfn.LET(_xlpm.headerRow, MATCH("Period", 'Reference Sheet'!A:A, 0), _xlpm.startRow, _xlpm.headerRow+1, IF(ROW()-ROW($A$29)+1>9, "N/A", IF(ISNUMBER(INDEX('Reference Sheet'!B:B, _xlpm.startRow+ROW()-ROW($A$29)-1)), INDEX('Reference Sheet'!B:B, _xlpm.startRow+ROW()-ROW($A$29)-1), "N/A")))} -> N/A | M36: {=_xlfn.LET(_xlpm.headerRow, MATCH("Period", 'Reference Sheet'!A:A, 0), _xlpm.startRow, _xlpm.headerRow+1, IF(ROW()-ROW($A$29)+1>9, "N/A", IF(ISNUMBER(INDEX('Reference Sheet'!C:C, _xlpm.startRow+ROW()-ROW($A$29)-1)), INDEX('Reference Sheet'!C:C, _xlpm.startRow+ROW()-ROW($A$29)-1), "N/A")))} -> N/A
A37: {=_xlfn.LET(_xlpm.startRow, MATCH("Period", 'Reference Sheet'!A:A, 0)+1, IF(ROW()-ROW($A$29)+1>9, "N/A", INDEX('Reference Sheet'!A:A, _xlpm.startRow+ROW()-ROW($A$29)-1)))} -> #N/A | G37: {=_xlfn.LET(_xlpm.headerRow, MATCH("Period", 'Reference Sheet'!A:A, 0), _xlpm.startRow, _xlpm.headerRow+1, IF(ROW()-ROW($A$29)+1>9, "N/A", IF(ISNUMBER(INDEX('Reference Sheet'!B:B, _xlpm.startRow+ROW()-ROW($A$29)-1)), INDEX('Reference Sheet'!B:B, _xlpm.startRow+ROW()-ROW($A$29)-1), "N/A")))} -> N/A | M37: {=_xlfn.LET(_xlpm.headerRow, MATCH("Period", 'Reference Sheet'!A:A, 0), _xlpm.startRow, _xlpm.headerRow+1, IF(ROW()-ROW($A$29)+1>9, "N/A", IF(ISNUMBER(INDEX('Reference Sheet'!C:C, _xlpm.startRow+ROW()-ROW($A$29)-1)), INDEX('Reference Sheet'!C:C, _xlpm.startRow+ROW()-ROW($A$29)-1), "N/A")))} -> N/A
A38: {=_xlfn.LET(_xlpm.startRow, MATCH("Period", 'Reference Sheet'!A:A, 0)+1, IF(ROW()-ROW($A$29)+1>9, "N/A", INDEX('Reference Sheet'!A:A, _xlpm.startRow+ROW()-ROW($A$29)-1)))} -> N/A | G38: {=_xlfn.LET(_xlpm.headerRow, MATCH("Period", 'Reference Sheet'!A:A, 0), _xlpm.startRow, _xlpm.headerRow+1, IF(ROW()-ROW($A$29)+1>9, "N/A", IF(ISNUMBER(INDEX('Reference Sheet'!B:B, _xlpm.startRow+ROW()-ROW($A$29)-1)), INDEX('Reference Sheet'!B:B, _xlpm.startRow+ROW()-ROW($A$29)-1), "N/A")))} -> N/A | M38: {=_xlfn.LET(_xlpm.headerRow, MATCH("Period", 'Reference Sheet'!A:A, 0), _xlpm.startRow, _xlpm.headerRow+1, IF(ROW()-ROW($A$29)+1>9, "N/A", IF(ISNUMBER(INDEX('Reference Sheet'!C:C, _xlpm.startRow+ROW()-ROW($A$29)-1)), INDEX('Reference Sheet'!C:C, _xlpm.startRow+ROW()-ROW($A$29)-1), "N/A")))} -> N/A
A39: {=_xlfn.LET(_xlpm.startRow, MATCH("Period", 'Reference Sheet'!A:A, 0)+1, IF(ROW()-ROW($A$29)+1>9, "N/A", INDEX('Reference Sheet'!A:A, _xlpm.startRow+ROW()-ROW($A$29)-1)))} -> N/A | G39: {=_xlfn.LET(_xlpm.headerRow, MATCH("Period", 'Reference Sheet'!A:A, 0), _xlpm.startRow, _xlpm.headerRow+1, IF(ROW()-ROW($A$29)+1>9, "N/A", IF(ISNUMBER(INDEX('Reference Sheet'!B:B, _xlpm.startRow+ROW()-ROW($A$29)-1)), INDEX('Reference Sheet'!B:B, _xlpm.startRow+ROW()-ROW($A$29)-1), "N/A")))} -> N/A | M39: {=_xlfn.LET(_xlpm.headerRow, MATCH("Period", 'Reference Sheet'!A:A, 0), _xlpm.startRow, _xlpm.headerRow+1, IF(ROW()-ROW($A$29)+1>9, "N/A", IF(ISNUMBER(INDEX('Reference Sheet'!C:C, _xlpm.startRow+ROW()-ROW($A$29)-1)), INDEX('Reference Sheet'!C:C, _xlpm.startRow+ROW()-ROW($A$29)-1), "N/A")))} -> N/A
A40: {=_xlfn.LET(_xlpm.startRow, MATCH("Period", 'Reference Sheet'!A:A, 0)+1, IF(ROW()-ROW($A$29)+1>9, "N/A", INDEX('Reference Sheet'!A:A, _xlpm.startRow+ROW()-ROW($A$29)-1)))} -> N/A | G40: {=_xlfn.LET(_xlpm.headerRow, MATCH("Period", 'Reference Sheet'!A:A, 0), _xlpm.startRow, _xlpm.headerRow+1, IF(ROW()-ROW($A$29)+1>9, "N/A", IF(ISNUMBER(INDEX('Reference Sheet'!B:B, _xlpm.startRow+ROW()-ROW($A$29)-1)), INDEX('Reference Sheet'!B:B, _xlpm.startRow+ROW()-ROW($A$29)-1), "N/A")))} -> N/A | M40: {=_xlfn.LET(_xlpm.headerRow, MATCH("Period", 'Reference Sheet'!A:A, 0), _xlpm.startRow, _xlpm.headerRow+1, IF(ROW()-ROW($A$29)+1>9, "N/A", IF(ISNUMBER(INDEX('Reference Sheet'!C:C, _xlpm.startRow+ROW()-ROW($A$29)-1)), INDEX('Reference Sheet'!C:C, _xlpm.startRow+ROW()-ROW($A$29)-1), "N/A")))} -> N/A
A41: {=_xlfn.LET(_xlpm.startRow, MATCH("Period", 'Reference Sheet'!A:A, 0)+1, IF(ROW()-ROW($A$29)+1>9, "N/A", INDEX('Reference Sheet'!A:A, _xlpm.startRow+ROW()-ROW($A$29)-1)))} -> N/A | G41: {=_xlfn.LET(_xlpm.headerRow, MATCH("Period", 'Reference Sheet'!A:A, 0), _xlpm.startRow, _xlpm.headerRow+1, IF(ROW()-ROW($A$29)+1>9, "N/A", IF(ISNUMBER(INDEX('Reference Sheet'!B:B, _xlpm.startRow+ROW()-ROW($A$29)-1)), INDEX('Reference Sheet'!B:B, _xlpm.startRow+ROW()-ROW($A$29)-1), "N/A")))} -> N/A | M41: {=_xlfn.LET(_xlpm.headerRow, MATCH("Period", 'Reference Sheet'!A:A, 0), _xlpm.startRow, _xlpm.headerRow+1, IF(ROW()-ROW($A$29)+1>9, "N/A", IF(ISNUMBER(INDEX('Reference Sheet'!C:C, _xlpm.startRow+ROW()-ROW($A$29)-1)), INDEX('Reference Sheet'!C:C, _xlpm.startRow+ROW()-ROW($A$29)-1), "N/A")))} -> N/A
... A43: {=_xlfn.LET(_xlpm.startRow, MATCH("Period", 'Reference Sheet'!A:A, 0)+1, IF(ROW()-ROW($A$29)+1>9, "N/A", INDEX('Reference Sheet'!A:A, _xlpm.startRow+ROW()-ROW($A$29)-1)))} -> N/A | G43: {=_xlfn.LET(_xlpm.headerRow, MATCH("Period", 'Reference Sheet'!A:A, 0), _xlpm.startRow, _xlpm.headerRow+1, IF(ROW()-ROW($A$29)+1>9, "N/A", IF(ISNUMBER(INDEX('Reference Sheet'!B:B, _xlpm.startRow+ROW()-ROW($A$29)-1)), INDEX('Reference Sheet'!B:B, _xlpm.startRow+ROW()-ROW($A$29)-1), "N/A")))} -> N/A | M43: {=_xlfn.LET(_xlpm.headerRow, MATCH("Period", 'Reference Sheet'!A:A, 0), _xlpm.startRow, _xlpm.headerRow+1, IF(ROW()-ROW($A$29)+1>9, "N/A", IF(ISNUMBER(INDEX('Reference Sheet'!C:C, _xlpm.startRow+ROW()-ROW($A$29)-1)), INDEX('Reference Sheet'!C:C, _xlpm.startRow+ROW()-ROW($A$29)-1), "N/A")))} -> N/A
A44: OPERATING EXPENESE REIMBURSEMENTS
A45: Cap on Controllable: | D45: =_xlfn.XLOOKUP(A45, 'Reference Sheet'!A:A, 'Reference Sheet'!B:B, "Not Found") -> Not Found
...

Sheet Reference Sheet
L2: Prompt to generate abstract in GPT (Always attach this template and Lease in GPT):
