Workbook

Sheet Cover
A1: THE COMMERCIAL REAL ESTATE MODEL Lease Financial Analysis
H6: PREPARED FOR
H7: Client
H8: PREPARED BY
H9: Ryan Arnold
H10: REPORT DATE
A11: PREPARED FOR Client | H11: 02.25.2026
H12: SCENARIO COUNT
H13: 3
A16: SCENARIO SNAPSHOT
A17: Scenario | E17: NPV Cost | G17: Total Obligation | I17: Equalized Total Obligation | K17: Average Price / SF | L17: Equalized Price / SF
A18: Benbrook Suite 200 - Option A | E18: =IFERROR(INDEX('Summary Comparison'!$A:$ZZ,MATCH("NPV cost",'Summary Comparison'!$A:$A,0),3),0) -> 794205.89 | G18: =IFERROR(INDEX('Summary Comparison'!$A:$ZZ,MATCH("Total obligation",'Summary Comparison'!$A:$A,0),3),0) -> 984135.24 | I18: =IFERROR(INDEX('Equalized Metrics'!$A:$ZZ,MATCH("Equalized total cost",'Equalized Metrics'!$A:$A,0),3),"—") | K18: =IFERROR(INDEX('Summary Comparison'!$A:$ZZ,MATCH("Avg cost/SF/year",'Summary Comparison'!$A:$A,0),3),0) -> 32.7 | L18: =IFERROR(INDEX('Equalized Metrics'!$A:$ZZ,MATCH("Equalized avg cost/SF/year",'Equalized Metrics'!$A:$A,0),3),"—")
A19: Benbrook Suite 200 - Option B | E19: =IFERROR(INDEX('Summary Comparison'!$A:$ZZ,MATCH("NPV cost",'Summary Comparison'!$A:$A,0),4),0) -> 1023746.4 | G19: =IFERROR(INDEX('Summary Comparison'!$A:$ZZ,MATCH("Total obligation",'Summary Comparison'!$A:$A,0),4),0) -> 1375834.1 | I19: =IFERROR(INDEX('Equalized Metrics'!$A:$ZZ,MATCH("Equalized total cost",'Equalized Metrics'!$A:$A,0),4),"—") | K19: =IFERROR(INDEX('Summary Comparison'!$A:$ZZ,MATCH("Avg cost/SF/year",'Summary Comparison'!$A:$A,0),4),0) -> 30.18 | L19: =IFERROR(INDEX('Equalized Metrics'!$A:$ZZ,MATCH("Equalized avg cost/SF/year",'Equalized Metrics'!$A:$A,0),4),"—")
A20: The Summit at Lantana Floor 3,4 | E20: =IFERROR(INDEX('Summary Comparison'!$A:$ZZ,MATCH("NPV cost",'Summary Comparison'!$A:$A,0),2),0) -> 23290151 | G20: =IFERROR(INDEX('Summary Comparison'!$A:$ZZ,MATCH("Total obligation",'Summary Comparison'!$A:$A,0),2),0) -> 31450512 | I20: =IFERROR(INDEX('Equalized Metrics'!$A:$ZZ,MATCH("Equalized total cost",'Equalized Metrics'!$A:$A,0),2),"—") | K20: =IFERROR(INDEX('Summary Comparison'!$A:$ZZ,MATCH("Avg cost/SF/year",'Summary Comparison'!$A:$A,0),2),0) -> 27.41 | L20: =IFERROR(INDEX('Equalized Metrics'!$A:$ZZ,MATCH("Equalized avg cost/SF/year",'Equalized Metrics'!$A:$A,0),2),"—")

Sheet Summary Comparison
A1: SUMMARY COMPARISON
B3: REPORT DATE 02.25.2026
A6: Metric | B6: The Summit at Lantana Floor 3,4 | C6: Benbrook Suite 200 - Option A | D6: Benbrook Suite 200 - Option B
A7: PREMISES
A8: Document type | B8: Counter Proposal | C8: Counter Proposal | D8: Counter Proposal
A9: Building name | B9: The Summit at Lantana | C9: Benbrook | D9: Benbrook
A10: Suite / floor | B10: Floor 3,4 | C10: 200 | D10: 200
A11: Street address | B11: 7171 SW Parkway
A12: RSF | B12: 114558 | C12: 4626 | D12: 4626
A13: Commencement | B13: 04.01.2028 | C13: 12.01.2026 | D13: 12.01.2026
A14: Expiration | B14: 08.31.2035 | C14: 02.29.2032 | D14: 03.31.2034
A15: RENT STRUCTURE
A16: Lease type | B16: MODIFIED GROSS | C16: NNN | D16: NNN
A17: Term (months) | B17: 89 | C17: 63 | D17: 88
A18: Rent (nominal) | B18: 31450512 | C18: 636838.29 | D18: 890720.88
A19: OpEx (nominal) | B19: 0 | C19: 347296.95 | D19: 485113.2
A20: OpEx escalation % | B20: 0.03 | C20: 0.03 | D20: 0.03
A21: Discount rate | B21: 0.08 | C21: 0.08 | D21: 0.08
A22: PARKING
A23: Parking cost ($/spot/month, pre-tax) | B23: 0 | C23: 0 | D23: 0
A24: Parking sales tax % | B24: 0.0825 | C24: 0.0825 | D24: 0.0825
A25: Parking cost ($/spot/month, after tax) | B25: =IFERROR(INDEX($A:$ZZ,MATCH("Parking cost ($/spot/month, pre-tax)",$A:$A,0),COLUMN())*(1+INDEX($A:$ZZ,MATCH("Parking sales tax %",$A:$A,0),COLUMN())),0) -> 0 | C25: =IFERROR(INDEX($A:$ZZ,MATCH("Parking cost ($/spot/month, pre-tax)",$A:$A,0),COLUMN())*(1+INDEX($A:$ZZ,MATCH("Parking sales tax %",$A:$A,0),COLUMN())),0) -> 0 | D25: =IFERROR(INDEX($A:$ZZ,MATCH("Parking cost ($/spot/month, pre-tax)",$A:$A,0),COLUMN())*(1+INDEX($A:$ZZ,MATCH("Parking sales tax %",$A:$A,0),COLUMN())),0) -> 0
A26: Parking cost (annual) | B26: 0 | C26: 0 | D26: 0
A27: TI / CAPEX
A28: TI budget | B28: 0 | C28: 0 | D28: 0
A29: TI allowance ($/SF) | B29: 0 | C29: 0 | D29: 0
A30: TI out of pocket | B30: 0 | C30: 0 | D30: 0
A31: SUMMARY METRICS
A32: Total obligation | B32: =IFERROR(INDEX('Monthly Gross Cash Flow Matrix'!$A:$ZZ,MATCH("Total Estimated Obligation",'Monthly Gross Cash Flow Matrix'!$B:$B,0),COLUMN()+1),0) -> 31450512 | C32: =IFERROR(INDEX('Monthly Gross Cash Flow Matrix'!$A:$ZZ,MATCH("Total Estimated Obligation",'Monthly Gross Cash Flow Matrix'!$B:$B,0),COLUMN()+1),0) -> 984135.24 | D32: =IFERROR(INDEX('Monthly Gross Cash Flow Matrix'!$A:$ZZ,MATCH("Total Estimated Obligation",'Monthly Gross Cash Flow Matrix'!$B:$B,0),COLUMN()+1),0) -> 1375834.1
A33: NPV cost | B33: 23290151 | C33: 794205.89 | D33: 1023746.4
A34: Avg cost/year | B34: =IFERROR(INDEX($A:$ZZ,MATCH("Total obligation",$A:$A,0),COLUMN())/(INDEX($A:$ZZ,MATCH("Term (months)",$A:$A,0),COLUMN())/12),0) -> 4240518.4 | C34: =IFERROR(INDEX($A:$ZZ,MATCH("Total obligation",$A:$A,0),COLUMN())/(INDEX($A:$ZZ,MATCH("Term (months)",$A:$A,0),COLUMN())/12),0) -> 187454.33 | D34: =IFERROR(INDEX($A:$ZZ,MATCH("Total obligation",$A:$A,0),COLUMN())/(INDEX($A:$ZZ,MATCH("Term (months)",$A:$A,0),COLUMN())/12),0) -> 187613.74
A35: Avg cost/SF/year | B35: =IFERROR(INDEX($A:$ZZ,MATCH("Avg cost/year",$A:$A,0),COLUMN())/INDEX($A:$ZZ,MATCH("RSF",$A:$A,0),COLUMN()),0) -> 27.41 | C35: =IFERROR(INDEX($A:$ZZ,MATCH("Avg cost/year",$A:$A,0),COLUMN())/INDEX($A:$ZZ,MATCH("RSF",$A:$A,0),COLUMN()),0) -> 32.7 | D35: =IFERROR(INDEX($A:$ZZ,MATCH("Avg cost/year",$A:$A,0),COLUMN())/INDEX($A:$ZZ,MATCH("RSF",$A:$A,0),COLUMN()),0) -> 30.18
A36: Equalized avg cost/RSF/yr | B36: =IFERROR(INDEX('Equalized Metrics'!$A:$ZZ,MATCH("Equalized avg cost/SF/year",'Equalized Metrics'!$A:$A,0),COLUMN()),0) -> 27.41 | C36: =IFERROR(INDEX('Equalized Metrics'!$A:$ZZ,MATCH("Equalized avg cost/SF/year",'Equalized Metrics'!$A:$A,0),COLUMN()),0) -> 32.7 | D36: =IFERROR(INDEX('Equalized Metrics'!$A:$ZZ,MATCH("Equalized avg cost/SF/year",'Equalized Metrics'!$A:$A,0),COLUMN()),0) -> 30.18
A37: Notes are listed in full on the Notes sheet.

Sheet Notes
A1: NOTES Scenario notes and clause highlights
C3: REPORT DATE 02.25.2026
A6: Scenario | B6: Notes
A7: The Summit at Lantana Floor 3,4 | B7: Full extracted notes
A8: • | B8: ROFR / ROFO: ROFR: RIGHT OF FIRST REFUSAL: Upon lease execution, SolarWinds shall have Right of First Refusal (“ROFR”) to lease additional space in the Building whether triggered by a Project occupant or otherwise
A9: • | B9: ROFR / ROFO: Use restrictions: USE: SolarWinds shall use the Premises for any legal purpose permitted by current zoning ordinances. The density limitation in Section 9.2 of SolarWinds’ existing lease shall be revised to :1000. ROFR: RIGHT OF FIRST REFUSAL: Upon lease execution, SolarWinds shall have Right of First Refusal (“ROFR”) to lease additional space in the Building whether triggered by a Project occupant or otherwise
A10: • | B10: Renewal / extension: Renewal option: INTERNAL STAIRWELL: SolarWinds shall have the right to install a mutually agreed upon internal stairwell in the Project. There shall be a restoration provision for the stairwell, the existing building lobby or any other
A11: • | B11: General: Use restrictions: USE: SolarWinds shall use the Premises for any legal purpose permitted by current zoning ordinances. The density limitation in Section 9.2 of SolarWinds’ existing lease shall be revised to :1000. Discount rate 8.00% applied with month-end discounting
A12: • | B12: General: no amortization of TI in monthly view.. Free-rent abatement applied for months 1-5 (base).
A13: • | B13: Operating expenses: upfront month-0 cashflows remain undiscounted.. Base rent and opex as provided
A14: Benbrook Suite 200 - Option A | B14: Full extracted notes
A15: • | B15: Assignment / sublease: Assignment/Sublease: RIGHT:The existing lease shall be amended so that Tenant shall have the continuing right to assign the lease or sublet all or any portion of the premises at any time during the primary term or any extensions thereof, wit. Assignment/Sublease: RIGHT:The existing lease shall be amended so that Tenant shall have the continuing right to assign the lease or sublet all or any portion of the premises at any time during the primary term or any extensions thereof, wit. Discount rate 8.00% applied with month-end discounting
A16: • | B16: Operating expenses: upfront month-0 cashflows remain undiscounted.. Base rent and opex as provided
A17: • | B17: General: no amortization of TI in monthly view.. Free-rent abatement applied for months 1-6 (base).
... A21: • | B21: General: no amortization of TI in monthly view.. Free-rent abatement applied for months 1-8 (base).

Sheet Equalized Metrics
A1: EQUALIZED METRICS Shared overlap period calculations
B3: REPORT DATE 02.25.2026
A6: Equalized Period: 04.01.2028 - 02.29.2032
A8: Metric | B8: The Summit at Lantana Floor 3,4 | C8: Benbrook Suite 200 - Option A | D8: Benbrook Suite 200 - Option B
A9: Equalized avg cost/SF/year | B9: =IFERROR(B12/(114558*3.917808219178),0) -> 33.503407 | C9: =IFERROR(C12/(4626*3.917808219178),0) -> 43.622179 | D9: =IFERROR(D12/(4626*3.917808219178),0) -> 42.535688
A10: Equalized avg cost/month | B10: =IFERROR(B12/47,0) -> 319933.5 | C10: =IFERROR(C12/47,0) -> 16821.251 | D10: =IFERROR(D12/47,0) -> 16402.287
A11: Equalized avg cost/year | B11: =IFERROR(B12/(47/12),0) -> 3839202 | C11: =IFERROR(C12/(47/12),0) -> 201855.02 | D11: =IFERROR(D12/(47/12),0) -> 196827.44
A12: Equalized total cost | B12: =IFERROR(SUM('Monthly Gross Cash Flow Matrix'!C28:C74),0) -> 15036874 | C12: =IFERROR(SUM('Monthly Gross Cash Flow Matrix'!D28:D74),0) -> 790598.82 | D12: =IFERROR(SUM('Monthly Gross Cash Flow Matrix'!E28:E74),0) -> 770907.48
A13: Equalized NPV (t0=start) | B13: =IFERROR(SUMPRODUCT('Monthly Gross Cash Flow Matrix'!C28:C74,1/POWER(1+0.00643403011,ROW('Monthly Gross Cash Flow Matrix'!C28:C74)-ROW('Monthly Gross Cash Flow Matrix'!C28))),0) -> 12782211 | C13: =IFERROR(SUMPRODUCT('Monthly Gross Cash Flow Matrix'!D28:D74,1/POWER(1+0.00643403011,ROW('Monthly Gross Cash Flow Matrix'!D28:D74)-ROW('Monthly Gross Cash Flow Matrix'!D28))),0) -> 683399.04 | D13: =IFERROR(SUMPRODUCT('Monthly Gross Cash Flow Matrix'!E28:E74,1/POWER(1+0.00643403011,ROW('Monthly Gross Cash Flow Matrix'!E28:E74)-ROW('Monthly Gross Cash Flow Matrix'!E28))),0) -> 666395.89

Sheet Monthly Gross Cash Flow Matrix
A1: MONTHLY GROSS CASH FLOW MATRIX Side-by-side monthly totals
B3: REPORT DATE 02.25.2026
A6: Month # | B6: Date | C6: The Summit at Lantana Floor 3,4 | D6: Benbrook Suite 200 - Option A | E6: Benbrook Suite 200 - Option B | G6: __parking_helper_1 | H6: __parking_helper_2 | I6: __parking_helper_3
A7: 0 | B7: PRE LEASE COMMENCEMENT | C7: 0 | D7: 0 | E7: 0
A8: TIB | B8: TI budget (Year 0 / PLC) | C8: 0 | D8: 0 | E8: 0
A9: TIA | B9: TI allowance credit (Year 0 / PLC) | C9: 0 | D9: 0 | E9: 0
A10: TIN | B10: TI net impact (budget - allowance) | C10: =C8+C9 -> 0 | D10: =D8+D9 -> 0 | E10: =E8+E9 -> 0
A11: PC | B11: Parking costs (term total) | C11: =SUM(G12:G116) -> 0 | D11: =SUM(H12:H116) -> 0 | E11: =SUM(I12:I116) -> 0
A12: 1 | B12: 12.01.2026 | C12: — | D12: 5512.65 | E12: 5512.65 | G12: 0 | H12: 0 | I12: 0
A13: 2 | B13: 01.01.2027 | C13: — | D13: 5512.65 | E13: 5512.65 | G13: 0 | H13: 0 | I13: 0
A14: 3 | B14: 02.01.2027 | C14: — | D14: 5512.65 | E14: 5512.65 | G14: 0 | H14: 0 | I14: 0
A15: 4 | B15: 03.01.2027 | C15: — | D15: 5512.65 | E15: 5512.65 | G15: 0 | H15: 0 | I15: 0
A16: 5 | B16: 04.01.2027 | C16: — | D16: 5512.65 | E16: 5512.65 | G16: 0 | H16: 0 | I16: 0
A17: 6 | B17: 05.01.2027 | C17: — | D17: 5512.65 | E17: 5512.65 | G17: 0 | H17: 0 | I17: 0
A18: 7 | B18: 06.01.2027 | C18: — | D18: 15921.15 | E18: 5512.65 | G18: 0 | H18: 0 | I18: 0
A19: 8 | B19: 07.01.2027 | C19: — | D19: 15921.15 | E19: 5512.65 | G19: 0 | H19: 0 | I19: 0
A20: 9 | B20: 08.01.2027 | C20: — | D20: 15921.15 | E20: 15535.65 | G20: 0 | H20: 0 | I20: 0
A21: 10 | B21: 09.01.2027 | C21: — | D21: 15921.15 | E21: 15535.65 | G21: 0 | H21: 0 | I21: 0
A22: 11 | B22: 10.01.2027 | C22: — | D22: 15921.15 | E22: 15535.65 | G22: 0 | H22: 0 | I22: 0
A23: 12 | B23: 11.01.2027 | C23: — | D23: 15921.15 | E23: 15535.65 | G23: 0 | H23: 0 | I23: 0
... A27: 16 | B27: 03.01.2028 | C27: — | D27: 16233.405 | E27: 15836.34 | G27: 0 | H27: 0 | I27: 0
A28: 17 | B28: 04.01.2028 | C28: 0 | D28: 16233.405 | E28: 15836.34 | G28: 0 | H28: 0 | I28: 0
A29: 18 | B29: 05.01.2028 | C29: 0 | D29: 16233.405 | E29: 15836.34 | G29: 0 | H29: 0 | I29: 0
A30: 19 | B30: 06.01.2028 | C30: 0 | D30: 16233.405 | E30: 15836.34 | G30: 0 | H30: 0 | I30: 0
A31: 20 | B31: 07.01.2028 | C31: 0 | D31: 16233.405 | E31: 15836.34 | G31: 0 | H31: 0 | I31: 0
A32: 21 | B32: 08.01.2028 | C32: 0 | D32: 16233.405 | E32: 15836.34 | G32: 0 | H32: 0 | I32: 0
A33: 22 | B33: 09.01.2028 | C33: 343674 | D33: 16233.405 | E33: 15836.34 | G33: 0 | H33: 0 | I33: 0
A34: 23 | B34: 10.01.2028 | C34: 343674 | D34: 16233.405 | E34: 15836.34 | G34: 0 | H34: 0 | I34: 0
A35: 24 | B35: 11.01.2028 | C35: 343674 | D35: 16233.405 | E35: 15836.34 | G35: 0 | H35: 0 | I35: 0
A36: 25 | B36: 12.01.2028 | C36: 343674 | D36: 16553.37 | E36: 16144.74 | G36: 0 | H36: 0 | I36: 0
A37: 26 | B37: 01.01.2029 | C37: 343674 | D37: 16553.37 | E37: 16144.74 | G37: 0 | H37: 0 | I37: 0
A38: 27 | B38: 02.01.2029 | C38: 343674 | D38: 16553.37 | E38: 16144.74 | G38: 0 | H38: 0 | I38: 0
A39: 28 | B39: 03.01.2029 | C39: 343674 | D39: 16553.37 | E39: 16144.74 | G39: 0 | H39: 0 | I39: 0
... A74: 63 | B74: 02.01.2032 | C74: 370099.67 | D74: 17578.8 | E74: 17131.62 | G74: 0 | H74: 0 | I74: 0
A75: 64 | B75: 03.01.2032 | C75: 370099.67 | D75: — | E75: 17131.62 | G75: 0 | H75: 0 | I75: 0
A76: 65 | B76: 04.01.2032 | C76: 379352.13 | D76: — | E76: 17131.62 | G76: 0 | H76: 0 | I76: 0
A77: 66 | B77: 05.01.2032 | C77: 379352.13 | D77: — | E77: 17131.62 | G77: 0 | H77: 0 | I77: 0
A78: 67 | B78: 06.01.2032 | C78: 379352.13 | D78: — | E78: 17131.62 | G78: 0 | H78: 0 | I78: 0
A79: 68 | B79: 07.01.2032 | C79: 379352.13 | D79: — | E79: 17131.62 | G79: 0 | H79: 0 | I79: 0
A80: 69 | B80: 08.01.2032 | C80: 379352.13 | D80: — | E80: 17131.62 | G80: 0 | H80: 0 | I80: 0
...

Sheet Appendix — The Summit at Lantan
A1: APPENDIX — MONTHLY CASH FLOWS The Summit at Lantana Floor 3,4
D3: REPORT DATE 02.25.2026
A6: The Summit at Lantana | Floor 3,4 | 04.01.2028 - 08.31.2035
A8: Month # | B8: Date | C8: Base Rent | D8: OpEx | E8: Parking | F8: Other Costs | G8: Gross Cash Flow | H8: Cumulative | I8: Present Value
A9: 0 | B9: PRE LEASE COMMENCEMENT | C9: 0 | D9: 0 | E9: 0 | F9: 0 | G9: =SUM(C9:F9) -> 0 | H9: =G9 -> 0 | I9: =IFERROR(G9/POWER(1+0.00643403011,A9),0) -> 0
A10: TIB | B10: TI budget (Year 0 / PLC) | C10: 0 | D10: 0 | E10: 0 | F10: 0 | G10: =SUM(C10:F10) -> 0 | H10: =H9+G10 -> 0 | I10: =G10 -> 0
A11: TIA | B11: TI allowance credit (Year 0 / PLC) | C11: 0 | D11: 0 | E11: 0 | F11: 0 | G11: =SUM(C11:F11) -> 0 | H11: =H10+G11 -> 0 | I11: =G11 -> 0
A12: 1 | B12: 04.01.2028 | C12: 0 | D12: 0 | E12: 0 | F12: 0 | G12: =SUM(C12:F12) -> 0 | H12: =H11+G12 -> 0 | I12: =IFERROR(G12/POWER(1+0.00643403011,A12),0) -> 0
A13: 2 | B13: 05.01.2028 | C13: 0 | D13: 0 | E13: 0 | F13: 0 | G13: =SUM(C13:F13) -> 0 | H13: =H12+G13 -> 0 | I13: =IFERROR(G13/POWER(1+0.00643403011,A13),0) -> 0
A14: 3 | B14: 06.01.2028 | C14: 0 | D14: 0 | E14: 0 | F14: 0 | G14: =SUM(C14:F14) -> 0 | H14: =H13+G14 -> 0 | I14: =IFERROR(G14/POWER(1+0.00643403011,A14),0) -> 0
A15: 4 | B15: 07.01.2028 | C15: 0 | D15: 0 | E15: 0 | F15: 0 | G15: =SUM(C15:F15) -> 0 | H15: =H14+G15 -> 0 | I15: =IFERROR(G15/POWER(1+0.00643403011,A15),0) -> 0
A16: 5 | B16: 08.01.2028 | C16: 0 | D16: 0 | E16: 0 | F16: 0 | G16: =SUM(C16:F16) -> 0 | H16: =H15+G16 -> 0 | I16: =IFERROR(G16/POWER(1+0.00643403011,A16),0) -> 0
A17: 6 | B17: 09.01.2028 | C17: 343674 | D17: 0 | E17: 0 | F17: 0 | G17: =SUM(C17:F17) -> 343674 | H17: =H16+G17 -> 343674 | I17: =IFERROR(G17/POWER(1+0.00643403011,A17),0) -> 330700.46
A18: 7 | B18: 10.01.2028 | C18: 343674 | D18: 0 | E18: 0 | F18: 0 | G18: =SUM(C18:F18) -> 343674 | H18: =H17+G18 -> 687348 | I18: =IFERROR(G18/POWER(1+0.00643403011,A18),0) -> 328586.33
A19: 8 | B19: 11.01.2028 | C19: 343674 | D19: 0 | E19: 0 | F19: 0 | G19: =SUM(C19:F19) -> 343674 | H19: =H18+G19 -> 1031022 | I19: =IFERROR(G19/POWER(1+0.00643403011,A19),0) -> 326485.71
A20: 9 | B20: 12.01.2028 | C20: 343674 | D20: 0 | E20: 0 | F20: 0 | G20: =SUM(C20:F20) -> 343674 | H20: =H19+G20 -> 1374696 | I20: =IFERROR(G20/POWER(1+0.00643403011,A20),0) -> 324398.52
A21: 10 | B21: 01.01.2029 | C21: 343674 | D21: 0 | E21: 0 | F21: 0 | G21: =SUM(C21:F21) -> 343674 | H21: =H20+G21 -> 1718370 | I21: =IFERROR(G21/POWER(1+0.00643403011,A21),0) -> 322324.67
A22: 11 | B22: 02.01.2029 | C22: 343674 | D22: 0 | E22: 0 | F22: 0 | G22: =SUM(C22:F22) -> 343674 | H22: =H21+G22 -> 2062044 | I22: =IFERROR(G22/POWER(1+0.00643403011,A22),0) -> 320264.08
A23: 12 | B23: 03.01.2029 | C23: 343674 | D23: 0 | E23: 0 | F23: 0 | G23: =SUM(C23:F23) -> 343674 | H23: =H22+G23 -> 2405718 | I23: =IFERROR(G23/POWER(1+0.00643403011,A23),0) -> 318216.67
... A100: 89 | B100: 08.01.2035 | C100: 408520.51 | D100: 0 | E100: 0 | F100: 0 | G100: =SUM(C100:F100) -> 408520.51 | H100: =H99+G100 -> 31450512 | I100: =IFERROR(G100/POWER(1+0.00643403011,A100),0) -> 230845.29
B101: Totals | C101: =SUM(C9:C100) | D101: =SUM(D9:D100) | E101: =SUM(E9:E100) | F101: =SUM(F9:F100) | G101: =SUM(G9:G100) | H101: =SUM(H9:H100) | I101: =SUM(I9:I100)

Sheet Appendix — Benbrook Suite 200 -
A1: APPENDIX — MONTHLY CASH FLOWS Benbrook Suite 200 - Option A
D3: REPORT DATE 02.25.2026
A6: Benbrook | 200 | 12.01.2026 - 02.29.2032
A8: Month # | B8: Date | C8: Base Rent | D8: OpEx | E8: Parking | F8: Other Costs | G8: Gross Cash Flow | H8: Cumulative | I8: Present Value
A9: 0 | B9: PRE LEASE COMMENCEMENT | C9: 0 | D9: 0 | E9: 0 | F9: 0 | G9: =SUM(C9:F9) -> 0 | H9: =G9 -> 0 | I9: =IFERROR(G9/POWER(1+0.00643403011,A9),0) -> 0
A10: TIB | B10: TI budget (Year 0 / PLC) | C10: 0 | D10: 0 | E10: 0 | F10: 0 | G10: =SUM(C10:F10) -> 0 | H10: =H9+G10 -> 0 | I10: =G10 -> 0
A11: TIA | B11: TI allowance credit (Year 0 / PLC) | C11: 0 | D11: 0 | E11: 0 | F11: 0 | G11: =SUM(C11:F11) -> 0 | H11: =H10+G11 -> 0 | I11: =G11 -> 0
A12: 1 | B12: 12.01.2026 | C12: 0 | D12: 5512.65 | E12: 0 | F12: 0 | G12: =SUM(C12:F12) -> 5512.65 | H12: =H11+G12 -> 5512.65 | I12: =IFERROR(G12/POWER(1+0.00643403011,A12),0) -> 5477.4082
A13: 2 | B13: 01.01.2027 | C13: 0 | D13: 5512.65 | E13: 0 | F13: 0 | G13: =SUM(C13:F13) -> 5512.65 | H13: =H12+G13 -> 11025.3 | I13: =IFERROR(G13/POWER(1+0.00643403011,A13),0) -> 5442.3917
A14: 3 | B14: 02.01.2027 | C14: 0 | D14: 5512.65 | E14: 0 | F14: 0 | G14: =SUM(C14:F14) -> 5512.65 | H14: =H13+G14 -> 16537.95 | I14: =IFERROR(G14/POWER(1+0.00643403011,A14),0) -> 5407.599
A15: 4 | B15: 03.01.2027 | C15: 0 | D15: 5512.65 | E15: 0 | F15: 0 | G15: =SUM(C15:F15) -> 5512.65 | H15: =H14+G15 -> 22050.6 | I15: =IFERROR(G15/POWER(1+0.00643403011,A15),0) -> 5373.0288
A16: 5 | B16: 04.01.2027 | C16: 0 | D16: 5512.65 | E16: 0 | F16: 0 | G16: =SUM(C16:F16) -> 5512.65 | H16: =H15+G16 -> 27563.25 | I16: =IFERROR(G16/POWER(1+0.00643403011,A16),0) -> 5338.6796
A17: 6 | B17: 05.01.2027 | C17: 0 | D17: 5512.65 | E17: 0 | F17: 0 | G17: =SUM(C17:F17) -> 5512.65 | H17: =H16+G17 -> 33075.9 | I17: =IFERROR(G17/POWER(1+0.00643403011,A17),0) -> 5304.5499
A18: 7 | B18: 06.01.2027 | C18: 10408.5 | D18: 5512.65 | E18: 0 | F18: 0 | G18: =SUM(C18:F18) -> 15921.15 | H18: =H17+G18 -> 48997.05 | I18: =IFERROR(G18/POWER(1+0.00643403011,A18),0) -> 15222.194
A19: 8 | B19: 07.01.2027 | C19: 10408.5 | D19: 5512.65 | E19: 0 | F19: 0 | G19: =SUM(C19:F19) -> 15921.15 | H19: =H18+G19 -> 64918.2 | I19: =IFERROR(G19/POWER(1+0.00643403011,A19),0) -> 15124.88
A20: 9 | B20: 08.01.2027 | C20: 10408.5 | D20: 5512.65 | E20: 0 | F20: 0 | G20: =SUM(C20:F20) -> 15921.15 | H20: =H19+G20 -> 80839.35 | I20: =IFERROR(G20/POWER(1+0.00643403011,A20),0) -> 15028.188
A21: 10 | B21: 09.01.2027 | C21: 10408.5 | D21: 5512.65 | E21: 0 | F21: 0 | G21: =SUM(C21:F21) -> 15921.15 | H21: =H20+G21 -> 96760.5 | I21: =IFERROR(G21/POWER(1+0.00643403011,A21),0) -> 14932.114
A22: 11 | B22: 10.01.2027 | C22: 10408.5 | D22: 5512.65 | E22: 0 | F22: 0 | G22: =SUM(C22:F22) -> 15921.15 | H22: =H21+G22 -> 112681.65 | I22: =IFERROR(G22/POWER(1+0.00643403011,A22),0) -> 14836.655
A23: 12 | B23: 11.01.2027 | C23: 10408.5 | D23: 5512.65 | E23: 0 | F23: 0 | G23: =SUM(C23:F23) -> 15921.15 | H23: =H22+G23 -> 128602.8 | I23: =IFERROR(G23/POWER(1+0.00643403011,A23),0) -> 14741.806
... A74: 63 | B74: 02.01.2032 | C74: 12066.15 | D74: 5512.65 | E74: 0 | F74: 0 | G74: =SUM(C74:F74) -> 17578.8 | H74: =H73+G74 -> 984135.24 | I74: =IFERROR(G74/POWER(1+0.00643403011,A74),0) -> 11735.849
B75: Totals | C75: =SUM(C9:C74) | D75: =SUM(D9:D74) | E75: =SUM(E9:E74) | F75: =SUM(F9:F74) | G75: =SUM(G9:G74) | H75: =SUM(H9:H74) | I75: =SUM(I9:I74)

Sheet Appendix — Benbrook Suite 2 (2)
A1: APPENDIX — MONTHLY CASH FLOWS Benbrook Suite 200 - Option B
D3: REPORT DATE 02.25.2026
A6: Benbrook | 200 | 12.01.2026 - 03.31.2034
A8: Month # | B8: Date | C8: Base Rent | D8: OpEx | E8: Parking | F8: Other Costs | G8: Gross Cash Flow | H8: Cumulative | I8: Present Value
A9: 0 | B9: PRE LEASE COMMENCEMENT | C9: 0 | D9: 0 | E9: 0 | F9: 0 | G9: =SUM(C9:F9) -> 0 | H9: =G9 -> 0 | I9: =IFERROR(G9/POWER(1+0.00643403011,A9),0) -> 0
A10: TIB | B10: TI budget (Year 0 / PLC) | C10: 0 | D10: 0 | E10: 0 | F10: 0 | G10: =SUM(C10:F10) -> 0 | H10: =H9+G10 -> 0 | I10: =G10 -> 0
A11: TIA | B11: TI allowance credit (Year 0 / PLC) | C11: 0 | D11: 0 | E11: 0 | F11: 0 | G11: =SUM(C11:F11) -> 0 | H11: =H10+G11 -> 0 | I11: =G11 -> 0
A12: 1 | B12: 12.01.2026 | C12: 0 | D12: 5512.65 | E12: 0 | F12: 0 | G12: =SUM(C12:F12) -> 5512.65 | H12: =H11+G12 -> 5512.65 | I12: =IFERROR(G12/POWER(1+0.00643403011,A12),0) -> 5477.4082
A13: 2 | B13: 01.01.2027 | C13: 0 | D13: 5512.65 | E13: 0 | F13: 0 | G13: =SUM(C13:F13) -> 5512.65 | H13: =H12+G13 -> 11025.3 | I13: =IFERROR(G13/POWER(1+0.00643403011,A13),0) -> 5442.3917
A14: 3 | B14: 02.01.2027 | C14: 0 | D14: 5512.65 | E14: 0 | F14: 0 | G14: =SUM(C14:F14) -> 5512.65 | H14: =H13+G14 -> 16537.95 | I14: =IFERROR(G14/POWER(1+0.00643403011,A14),0) -> 5407.599
A15: 4 | B15: 03.01.2027 | C15: 0 | D15: 5512.65 | E15: 0 | F15: 0 | G15: =SUM(C15:F15) -> 5512.65 | H15: =H14+G15 -> 22050.6 | I15: =IFERROR(G15/POWER(1+0.00643403011,A15),0) -> 5373.0288
A16: 5 | B16: 04.01.2027 | C16: 0 | D16: 5512.65 | E16: 0 | F16: 0 | G16: =SUM(C16:F16) -> 5512.65 | H16: =H15+G16 -> 27563.25 | I16: =IFERROR(G16/POWER(1+0.00643403011,A16),0) -> 5338.6796
A17: 6 | B17: 05.01.2027 | C17: 0 | D17: 5512.65 | E17: 0 | F17: 0 | G17: =SUM(C17:F17) -> 5512.65 | H17: =H16+G17 -> 33075.9 | I17: =IFERROR(G17/POWER(1+0.00643403011,A17),0) -> 5304.5499
A18: 7 | B18: 06.01.2027 | C18: 0 | D18: 5512.65 | E18: 0 | F18: 0 | G18: =SUM(C18:F18) -> 5512.65 | H18: =H17+G18 -> 38588.55 | I18: =IFERROR(G18/POWER(1+0.00643403011,A18),0) -> 5270.6385
A19: 8 | B19: 07.01.2027 | C19: 0 | D19: 5512.65 | E19: 0 | F19: 0 | G19: =SUM(C19:F19) -> 5512.65 | H19: =H18+G19 -> 44101.2 | I19: =IFERROR(G19/POWER(1+0.00643403011,A19),0) -> 5236.9438
A20: 9 | B20: 08.01.2027 | C20: 10023 | D20: 5512.65 | E20: 0 | F20: 0 | G20: =SUM(C20:F20) -> 15535.65 | H20: =H19+G20 -> 59636.85 | I20: =IFERROR(G20/POWER(1+0.00643403011,A20),0) -> 14664.309
A21: 10 | B21: 09.01.2027 | C21: 10023 | D21: 5512.65 | E21: 0 | F21: 0 | G21: =SUM(C21:F21) -> 15535.65 | H21: =H20+G21 -> 75172.5 | I21: =IFERROR(G21/POWER(1+0.00643403011,A21),0) -> 14570.562
A22: 11 | B22: 10.01.2027 | C22: 10023 | D22: 5512.65 | E22: 0 | F22: 0 | G22: =SUM(C22:F22) -> 15535.65 | H22: =H21+G22 -> 90708.15 | I22: =IFERROR(G22/POWER(1+0.00643403011,A22),0) -> 14477.414
A23: 12 | B23: 11.01.2027 | C23: 10023 | D23: 5512.65 | E23: 0 | F23: 0 | G23: =SUM(C23:F23) -> 15535.65 | H23: =H22+G23 -> 106243.8 | I23: =IFERROR(G23/POWER(1+0.00643403011,A23),0) -> 14384.861
... A99: 88 | B99: 03.01.2034 | C99: 12328.29 | D99: 5512.65 | E99: 0 | F99: 0 | G99: =SUM(C99:F99) -> 17840.94 | H99: =H98+G99 -> 1375834.1 | I99: =IFERROR(G99/POWER(1+0.00643403011,A99),0) -> 10146.358
B100: Totals | C100: =SUM(C9:C99) | D100: =SUM(D9:D99) | E100: =SUM(E9:E99) | F100: =SUM(F9:F99) | G100: =SUM(G9:G99) | H100: =SUM(H9:H99) | I100: =SUM(I9:I99)
